import express from 'express';
require('express-async-errors');

import cors from 'cors';
import morgan from 'morgan';

import { connectToDatabase } from './utils/db';
import init from './utils/init';

import config from './utils/config';
import { unknownEndpoint, errorHandler } from './utils/middleware';

import devRouter from './controllers/dev';
import loginRouter from './controllers/auth';
import studentRouter from './controllers/student';
import teacherRouter from './controllers/teacher';
import { requestLogger } from './utils/middleware';
import subjectRouter from './controllers/subject';
import studyClassRouter from './controllers/studyClass';
import activeSubjectRouter from './controllers/activeSubject';
// import logger from './utils/logger';

const app = express();

app.use(
  cors({
    origin: 'http://localhost:4200',
    credentials: true,
  })
);
app.use(express.json());

// Unsure about the cause of this...
// eslint-disable-next-line @typescript-eslint/no-unsafe-call
if (config.NODE_ENV === 'DEV') app.use(requestLogger);
app.use(morgan('tiny'));

if (config.NODE_ENV !== 'PROD') app.use('/', devRouter);

app.use('/api/auth/', loginRouter);
app.use('/api/student/', studentRouter);
app.use('/api/teacher/', teacherRouter);
app.use('/api/subject/', subjectRouter);
app.use('/api/studyClass/', studyClassRouter);
app.use('/api/activeSubject/', activeSubjectRouter);

app.get('/api/ping', (_, response) => {
  response.send('<p>pong</p>');
});

app.get('/api/failping', (_, response) => {
  response.status(400).send();
});

app.use(unknownEndpoint);
app.use(errorHandler);

const initServer = async () => {
  await connectToDatabase();
  await init();
};

export { app, initServer };
